2024-08-14 08:36:56,226 INFO: Bookstore application startup [in /root/GoodBooksBot/app.py:27]
2024-08-14 08:40:14,443 INFO: Bookstore application startup [in /root/GoodBooksBot/app.py:27]
2024-08-14 08:42:27,061 INFO: Bookstore application startup [in /root/GoodBooksBot/app.py:27]
2024-08-14 08:50:41,215 INFO: Bookstore application startup [in /root/GoodBooksBot/app.py:27]
2024-08-14 08:54:11,753 INFO: Bookstore application startup [in /root/GoodBooksBot/app.py:27]
2024-08-14 09:01:41,605 INFO: Bookstore application startup [in /root/GoodBooksBot/app.py:27]
2024-08-15 07:11:17,041 INFO: Bookstore application startup [in /root/GoodBooksBot/app.py:36]
2024-08-15 07:11:27,386 INFO: Bookstore application startup [in /root/GoodBooksBot/app.py:36]
2024-08-15 07:13:23,627 ERROR: Exception on /upload [POST] [in /root/GoodBooksBot/venv/lib/python3.12/site-packages/flask/app.py:838]
Traceback (most recent call last):
  File "/root/GoodBooksBot/venv/lib/python3.12/site-packages/flask/app.py", line 1473, in wsgi_app
    response = self.full_dispatch_request()
               ^^^^^^^^^^^^^^^^^^^^^^^^^^^^
  File "/root/GoodBooksBot/venv/lib/python3.12/site-packages/flask/app.py", line 882, in full_dispatch_request
    rv = self.handle_user_exception(e)
         ^^^^^^^^^^^^^^^^^^^^^^^^^^^^^
  File "/root/GoodBooksBot/venv/lib/python3.12/site-packages/flask/app.py", line 880, in full_dispatch_request
    rv = self.dispatch_request()
         ^^^^^^^^^^^^^^^^^^^^^^^
  File "/root/GoodBooksBot/venv/lib/python3.12/site-packages/flask/app.py", line 865, in dispatch_request
    return self.ensure_sync(self.view_functions[rule.endpoint])(**view_args)  # type: ignore[no-any-return]
           ^^^^^^^^^^^^^^^^^^^^^^^^^^^^^^^^^^^^^^^^^^^^^^^^^^^^^^^^^^^^^^^^^
  File "/root/GoodBooksBot/app.py", line 65, in upload_file
    flash('Файл успешно загружен и обработан.')
  File "/root/GoodBooksBot/venv/lib/python3.12/site-packages/flask/helpers.py", line 323, in flash
    session["_flashes"] = flashes
    ~~~~~~~^^^^^^^^^^^^
  File "/root/GoodBooksBot/venv/lib/python3.12/site-packages/flask/sessions.py", line 102, in _fail
    raise RuntimeError(
RuntimeError: The session is unavailable because no secret key was set.  Set the secret_key on the application to something unique and secret.
2024-08-15 07:14:09,942 INFO: Bookstore application startup [in /root/GoodBooksBot/app.py:36]
2024-08-15 07:18:13,337 ERROR: Exception on /upload [POST] [in /root/GoodBooksBot/venv/lib/python3.12/site-packages/flask/app.py:838]
Traceback (most recent call last):
  File "/root/GoodBooksBot/venv/lib/python3.12/site-packages/flask/app.py", line 1473, in wsgi_app
    response = self.full_dispatch_request()
               ^^^^^^^^^^^^^^^^^^^^^^^^^^^^
  File "/root/GoodBooksBot/venv/lib/python3.12/site-packages/flask/app.py", line 882, in full_dispatch_request
    rv = self.handle_user_exception(e)
         ^^^^^^^^^^^^^^^^^^^^^^^^^^^^^
  File "/root/GoodBooksBot/venv/lib/python3.12/site-packages/flask/app.py", line 880, in full_dispatch_request
    rv = self.dispatch_request()
         ^^^^^^^^^^^^^^^^^^^^^^^
  File "/root/GoodBooksBot/venv/lib/python3.12/site-packages/flask/app.py", line 865, in dispatch_request
    return self.ensure_sync(self.view_functions[rule.endpoint])(**view_args)  # type: ignore[no-any-return]
           ^^^^^^^^^^^^^^^^^^^^^^^^^^^^^^^^^^^^^^^^^^^^^^^^^^^^^^^^^^^^^^^^^
  File "/root/GoodBooksBot/app.py", line 65, in upload_file
    flash('Файл успешно загружен и обработан.')
  File "/root/GoodBooksBot/venv/lib/python3.12/site-packages/flask/helpers.py", line 323, in flash
    session["_flashes"] = flashes
    ~~~~~~~^^^^^^^^^^^^
  File "/root/GoodBooksBot/venv/lib/python3.12/site-packages/flask/sessions.py", line 102, in _fail
    raise RuntimeError(
RuntimeError: The session is unavailable because no secret key was set.  Set the secret_key on the application to something unique and secret.
2024-08-15 07:24:34,359 INFO: Bookstore application startup [in /root/GoodBooksBot/app.py:36]
2024-08-15 07:28:14,804 INFO: Bookstore application startup [in /root/GoodBooksBot/app.py:36]
2024-08-15 07:28:39,062 ERROR: Exception on /upload [POST] [in /root/GoodBooksBot/venv/lib/python3.12/site-packages/flask/app.py:838]
Traceback (most recent call last):
  File "/root/GoodBooksBot/venv/lib/python3.12/site-packages/flask/app.py", line 1473, in wsgi_app
    response = self.full_dispatch_request()
               ^^^^^^^^^^^^^^^^^^^^^^^^^^^^
  File "/root/GoodBooksBot/venv/lib/python3.12/site-packages/flask/app.py", line 882, in full_dispatch_request
    rv = self.handle_user_exception(e)
         ^^^^^^^^^^^^^^^^^^^^^^^^^^^^^
  File "/root/GoodBooksBot/venv/lib/python3.12/site-packages/flask/app.py", line 880, in full_dispatch_request
    rv = self.dispatch_request()
         ^^^^^^^^^^^^^^^^^^^^^^^
  File "/root/GoodBooksBot/venv/lib/python3.12/site-packages/flask/app.py", line 865, in dispatch_request
    return self.ensure_sync(self.view_functions[rule.endpoint])(**view_args)  # type: ignore[no-any-return]
           ^^^^^^^^^^^^^^^^^^^^^^^^^^^^^^^^^^^^^^^^^^^^^^^^^^^^^^^^^^^^^^^^^
  File "/root/GoodBooksBot/app.py", line 69, in upload_file
    flash('Файл успешно загружен и обработан.')
  File "/root/GoodBooksBot/venv/lib/python3.12/site-packages/flask/helpers.py", line 323, in flash
    session["_flashes"] = flashes
    ~~~~~~~^^^^^^^^^^^^
  File "/root/GoodBooksBot/venv/lib/python3.12/site-packages/flask/sessions.py", line 102, in _fail
    raise RuntimeError(
RuntimeError: The session is unavailable because no secret key was set.  Set the secret_key on the application to something unique and secret.
2024-08-15 07:29:56,397 INFO: Bookstore application startup [in /root/GoodBooksBot/app.py:36]
2024-08-15 07:30:21,597 ERROR: Exception on /upload [POST] [in /root/GoodBooksBot/venv/lib/python3.12/site-packages/flask/app.py:838]
Traceback (most recent call last):
  File "/root/GoodBooksBot/venv/lib/python3.12/site-packages/flask/app.py", line 1473, in wsgi_app
    response = self.full_dispatch_request()
               ^^^^^^^^^^^^^^^^^^^^^^^^^^^^
  File "/root/GoodBooksBot/venv/lib/python3.12/site-packages/flask/app.py", line 882, in full_dispatch_request
    rv = self.handle_user_exception(e)
         ^^^^^^^^^^^^^^^^^^^^^^^^^^^^^
  File "/root/GoodBooksBot/venv/lib/python3.12/site-packages/flask/app.py", line 880, in full_dispatch_request
    rv = self.dispatch_request()
         ^^^^^^^^^^^^^^^^^^^^^^^
  File "/root/GoodBooksBot/venv/lib/python3.12/site-packages/flask/app.py", line 865, in dispatch_request
    return self.ensure_sync(self.view_functions[rule.endpoint])(**view_args)  # type: ignore[no-any-return]
           ^^^^^^^^^^^^^^^^^^^^^^^^^^^^^^^^^^^^^^^^^^^^^^^^^^^^^^^^^^^^^^^^^
  File "/root/GoodBooksBot/app.py", line 69, in upload_file
    flash('Файл успешно загружен и обработан.')
  File "/root/GoodBooksBot/venv/lib/python3.12/site-packages/flask/helpers.py", line 323, in flash
    session["_flashes"] = flashes
    ~~~~~~~^^^^^^^^^^^^
  File "/root/GoodBooksBot/venv/lib/python3.12/site-packages/flask/sessions.py", line 102, in _fail
    raise RuntimeError(
RuntimeError: The session is unavailable because no secret key was set.  Set the secret_key on the application to something unique and secret.
2024-08-15 07:30:36,571 ERROR: Exception on /upload [POST] [in /root/GoodBooksBot/venv/lib/python3.12/site-packages/flask/app.py:838]
Traceback (most recent call last):
  File "/root/GoodBooksBot/venv/lib/python3.12/site-packages/flask/app.py", line 1473, in wsgi_app
    response = self.full_dispatch_request()
               ^^^^^^^^^^^^^^^^^^^^^^^^^^^^
  File "/root/GoodBooksBot/venv/lib/python3.12/site-packages/flask/app.py", line 882, in full_dispatch_request
    rv = self.handle_user_exception(e)
         ^^^^^^^^^^^^^^^^^^^^^^^^^^^^^
  File "/root/GoodBooksBot/venv/lib/python3.12/site-packages/flask/app.py", line 880, in full_dispatch_request
    rv = self.dispatch_request()
         ^^^^^^^^^^^^^^^^^^^^^^^
  File "/root/GoodBooksBot/venv/lib/python3.12/site-packages/flask/app.py", line 865, in dispatch_request
    return self.ensure_sync(self.view_functions[rule.endpoint])(**view_args)  # type: ignore[no-any-return]
           ^^^^^^^^^^^^^^^^^^^^^^^^^^^^^^^^^^^^^^^^^^^^^^^^^^^^^^^^^^^^^^^^^
  File "/root/GoodBooksBot/app.py", line 69, in upload_file
    flash('Файл успешно загружен и обработан.')
  File "/root/GoodBooksBot/venv/lib/python3.12/site-packages/flask/helpers.py", line 323, in flash
    session["_flashes"] = flashes
    ~~~~~~~^^^^^^^^^^^^
  File "/root/GoodBooksBot/venv/lib/python3.12/site-packages/flask/sessions.py", line 102, in _fail
    raise RuntimeError(
RuntimeError: The session is unavailable because no secret key was set.  Set the secret_key on the application to something unique and secret.
2024-08-15 07:32:42,108 INFO: Bookstore application startup [in /root/GoodBooksBot/app.py:38]
2024-08-15 07:39:43,993 INFO: Bookstore application startup [in /root/GoodBooksBot/app.py:38]
2024-08-15 07:49:29,930 INFO: Bookstore application startup [in /root/GoodBooksBot/app.py:38]
2024-08-15 07:54:49,792 INFO: Bookstore application startup [in /root/GoodBooksBot/app.py:38]
2024-08-15 08:00:29,272 INFO: Bookstore application startup [in /root/GoodBooksBot/app.py:38]
2024-08-15 08:00:56,920 INFO: Bookstore application startup [in /root/GoodBooksBot/app.py:38]
2024-08-15 08:02:13,791 INFO: Bookstore application startup [in /root/GoodBooksBot/app.py:38]
2024-08-15 08:03:12,782 INFO: Bookstore application startup [in /root/GoodBooksBot/app.py:38]
2024-08-15 08:06:20,366 INFO: Bookstore application startup [in /root/GoodBooksBot/app.py:38]
2024-08-15 08:19:44,664 INFO: Bookstore application startup [in /root/GoodBooksBot/app.py:38]
2024-08-15 08:20:48,422 INFO: Bookstore application startup [in /root/GoodBooksBot/app.py:38]
2024-08-15 08:25:38,693 INFO: Bookstore application startup [in /root/GoodBooksBot/app.py:38]
